<?xml version="1.0" encoding="UTF-8" ?>
<robot name="wheel" xmlns:xacro="http://ros.org/wiki/xacro">
  <xacro:macro name="wheel" params="parent prefix">

    <!-- Left wheel -->
    <joint name="${prefix}_l_drive_wheel_joint" type="continuous">
      <parent link="${parent}" />
      <child link="${prefix}_l_drive_wheel_link" />
      <origin xyz="0.0 0.100 0.045" rpy="0 0 0" />
      <axis xyz="0 1 0" />
      <limit velocity="10" effort="100" />
    </joint>
    
    <link name="${prefix}_l_drive_wheel_link">
      <visual>
        <origin xyz="0 0 0" rpy="${M_PI / 2.0} 0 0" />
        <geometry>
          <cylinder length="0.025" radius="0.045" />
        </geometry>
        <material name="tire" />
      </visual>

      <collision>
        <origin xyz="0 0 0" rpy="${M_PI / 2.0} 0 0" />
        <geometry>
          <cylinder length="0.025" radius="0.045" />
        </geometry>
        <material name="tire" />
      </collision>

      <inertial>
        <origin xyz="0 0 0" rpy="0 0 0" />
        <mass value="0.2" />
        <inertia ixx="0.001" ixy="0" ixz="0"
                 iyy="0.001" iyz="0"
                 izz="0.001" />
      </inertial>
    </link>


    <!-- Right wheel -->
    <joint name="${prefix}_r_drive_wheel_joint" type="continuous">
      <parent link="${parent}" />
      <child link="${prefix}_r_drive_wheel_link" />
      <origin xyz="0.0 -0.100 0.045" rpy="0 0 0" />
      <axis xyz="0 1 0" />
      <limit velocity="10" effort="100" />
    </joint>

    <link name="${prefix}_r_drive_wheel_link">
      <visual>
        <origin xyz="0 0 0" rpy="${M_PI / 2.0} 0 0" />
        <geometry>
          <cylinder length="0.025" radius="0.045" />
        </geometry>
        <material name="tire" />
      </visual>

      <collision>
        <origin xyz="0 0 0" rpy="${M_PI / 2.0} 0 0" />
        <geometry>
          <cylinder length="0.025" radius="0.045" />
        </geometry>
        <material name="tire" />
      </collision>

      <inertial>
        <origin xyz="0 0 0" rpy="0 0 0" />
        <mass value="0.2" />
        <inertia ixx="0.001" ixy="0" ixz="0"
                 iyy="0.001" iyz="0"
                 izz="0.001" />
      </inertial>
    </link>

  </xacro:macro>
</robot>
