<?xml version="1.0" encoding="UTF-8" ?>
<!-- OpenManipulator X1000 (Arm) -->
<robot name="arm" xmlns:xacro="http://ros.org/wiki/xacro">
  <xacro:include filename="$(find sobit_light_description)/urdf/arm/arm.transmission.xacro" />
  <xacro:macro name="arm" params="prefix parent">

    <!-- Joint 0: Platform -->
    <joint name="${prefix}_platform_joint" type="fixed">
      <parent link="${parent}"/>
      <child link="${prefix}_platform_link"/>
      <origin xyz="0.122 0.0 0.0" rpy="0 0 0"/>
    </joint>

    <!-- Link 0: Platform -->
    <link name="${prefix}_platform_link">
      <visual>
        <origin xyz="0 0 0" rpy="0 0 ${M_PI/2}"/>
        <geometry>
          <mesh filename="file://$(find sobit_light_description)/meshes/arm/omx1_link_base.stl" scale="0.001 0.001 0.001"/>
        </geometry>
        <material name="grey"/>
      </visual>

      <collision>
        <origin xyz="${0.005-0.1/2} 0.0 ${-0.0156+0.0686/2}" rpy="0 0 0"/>
        <geometry>
          <box size="0.1000 0.1200 0.0686"/>
        </geometry>
      </collision>

      <inertial>
        <origin xyz="${0.005-0.1/2} 0.0 ${-0.0156+0.0686/2}" rpy="0 0 0"/>
        <mass value="0.336" />
        <inertia  ixx="${1/12*0.336*(0.1000**2+0.0686**2)}" ixy="0.0" ixz="0.0"
                  iyy="${1/12*0.336*(0.1200**2+0.0686**2)}" iyz="0.0"
                  izz="${1/12*0.336*(0.1000**2+0.1200**2)}" />
      </inertial>
    </link>

    <!-- Joint 1: Base -->
    <joint name="${prefix}_base_joint" type="fixed">
      <parent link="${prefix}_platform_link"/>
      <child link="${prefix}_base_link"/>
      <origin xyz="${-0.0112-0.016/2} 0.0 0.008" rpy="0 0 0"/>
    </joint>

    <!-- Link 1: Base -->
    <link name="${prefix}_base_link">
      <visual>
        <origin xyz="0 0 0" rpy="0 0 ${M_PI/2}"/>
        <geometry>
          <mesh filename="file://$(find sobit_light_description)/meshes/arm/omx1_link1.stl" scale="0.001 0.001 0.001"/>
        </geometry>
        <material name="grey"/>
      </visual>

      <collision>
        <origin xyz="0.0 0.0 ${0.0585/2}" rpy="0 0 0"/>
        <geometry>
          <box size="0.0440 0.0335 0.0585"/>
        </geometry>
      </collision>

      <inertial>
        <origin xyz="0.0 0.0 ${0.0585/2}" rpy="0 0 0"/>
        <mass value="0.205" />
        <inertia  ixx="${1/12*0.205*(0.0440**2+0.0585**2)}" ixy="0.0" ixz="0.0"
                  iyy="${1/12*0.205*(0.0335**2+0.0585**2)}" iyz="0.0"
                  izz="${1/12*0.205*(0.0440**2+0.0335**2)}" />
      </inertial>
    </link>

    <!-- Joint 2: Shoulder -->
    <joint name="${prefix}_1_joint" type="revolute">
      <parent link="${prefix}_base_link"/>
      <child link="${prefix}_1_link"/>
      <origin xyz="0.0 0.0 0.0465" rpy="0 ${M_PI/2} 0"/>
      <axis xyz="0 0 1"/>
      <limit velocity="4.8" effort="1" lower="${-M_PI}" upper="${M_PI}" />
    </joint>

    <!--  Link 2: Shoulder -->
    <link name="${prefix}_1_link">
      <visual>
        <origin xyz="0 0 0.0" rpy="0 0 ${M_PI/2}"/>
        <geometry>
          <mesh filename="file://$(find sobit_light_description)/meshes/arm/omx1_link2.stl" scale="0.001 0.001 0.001"/>
        </geometry>
        <material name="grey"/>
      </visual>

      <collision>
        <origin xyz="0.0 0.0 ${0.0647/2}" rpy="0 0 0"/>
        <geometry>
          <box size="0.0335 0.1130 0.0647"/>
        </geometry>
      </collision>

      <inertial>
        <origin xyz="0.0 0.0 ${0.0647/2}" rpy="0 0 0"/>
        <mass value="0.392" />
        <inertia  ixx="${1/12*0.392*(0.0335**2+0.0647**2)}" ixy="0.0" ixz="0.0"
                  iyy="${1/12*0.392*(0.1130**2+0.0647**2)}" iyz="0.0"
                  izz="${1/12*0.392*(0.0335**2+0.1130**2)}" />
      </inertial>
    </link>

    <!--  Joint 3: Upper Arm -->
    <joint name="${prefix}_2_joint" type="revolute">
      <parent link="${prefix}_1_link"/>
      <child link="${prefix}_2_link"/>
      <origin xyz="0.0 0.0 0.05095" rpy="0 0 0"/>
      <axis xyz="0 1 0"/>
      <limit velocity="4.8" effort="1" lower="${-M_PI/2}" upper="${M_PI/2}" />
    </joint>

    <!--  Link 3: Upper Arm -->
    <link name="${prefix}_2_link">
      <visual>
        <origin xyz="0 0 0" rpy="0 0 ${M_PI/2}"/>
        <geometry>
          <mesh filename="file://$(find sobit_light_description)/meshes/arm/omx1_link3.stl" scale="0.001 0.001 0.001"/>
        </geometry>
        <material name="grey"/>
      </visual>

      <collision>
        <origin xyz="${0.03575-0.0585/2} 0.0 ${-0.016+(0.14475+0.016)/2}" rpy="0 0 0"/>
        <geometry>
          <box size="0.0585 0.0440 ${0.14475+0.016}"/>
        </geometry>
      </collision>

      <inertial>
        <origin xyz="${0.03575-0.0585/2} 0.0 ${-0.016+(0.14475+0.016)/2}" rpy="0 0 0"/>
        <mass value="0.261" />
        <inertia  ixx="${1/12*0.261*(0.0585**2+(0.14475+0.016)**2)}" ixy="0.0" ixz="0.0"
                  iyy="${1/12*0.261*(0.0440**2+(0.14475+0.016)**2)}" iyz="0.0"
                  izz="${1/12*0.261*(0.0585**2+0.0440**2)}" />
      </inertial>
    </link>

    <!--  Joint 3: Upper Arm (SUB) -->
    <joint name="${prefix}_2_sub_joint" type="revolute">
      <parent link="${prefix}_1_link"/>
      <child link="${prefix}_2_sub_link"/>
      <origin xyz="0.0 0.0 0.05095" rpy="0 0 0"/>
      <axis xyz="0 1 0"/>
      <limit velocity="4.8" effort="1" lower="${-M_PI/2}" upper="${M_PI/2}" />
      <mimic joint="${prefix}_2_joint" multiplier="-1" offset="0"/>
    </joint>

    <!--  Link 3: Upper Arm (SUB) -->
    <link name="${prefix}_2_sub_link">
      <!-- <visual>
        <origin xyz="0 0 0" rpy="0 0 ${M_PI/2}"/>
        <geometry>
          <mesh filename="file://$(find sobit_light_description)/meshes/arm/omx1_link3.stl" scale="0.001 0.001 0.001"/>
        </geometry>
        <material name="grey"/>
      </visual>

      <collision>
        <origin xyz="${0.03575-0.0585/2} 0.0 ${-0.016+(0.14475+0.016)/2}" rpy="0 0 0"/>
        <geometry>
          <box size="0.0585 0.0440 ${0.14475+0.016}"/>
        </geometry>
      </collision>

      <inertial>
        <origin xyz="${0.03575-0.0585/2} 0.0 ${-0.016+(0.14475+0.016)/2}" rpy="0 0 0"/>
        <mass value="0.261" />
        <inertia  ixx="${1/12*0.261*(0.0585**2+(0.14475+0.016)**2)}" ixy="0.0" ixz="0.0"
                  iyy="${1/12*0.261*(0.0440**2+(0.14475+0.016)**2)}" iyz="0.0"
                  izz="${1/12*0.261*(0.0585**2+0.0440**2)}" />
      </inertial> -->
    </link>

    <!--  Joint 4: Lower Arm -->
    <joint name="${prefix}_3_joint" type="revolute">
      <parent link="${prefix}_2_link"/>
      <child link="${prefix}_3_link"/>
      <origin xyz="0.022 -0.0 0.128" rpy="0 0 0"/>
      <axis xyz="0 1 0"/>
      <limit velocity="4.8" effort="1" lower="${-M_PI/2}" upper="${M_PI/2}" />
    </joint>

    <!--  Link 4: Lower Arm -->
    <link name="${prefix}_3_link">
      <visual>
        <origin xyz="0 0 0" rpy="0 0 ${M_PI/2}"/>
        <geometry>
          <mesh filename="file://$(find sobit_light_description)/meshes/arm/omx1_link4.stl" scale="0.001 0.001 0.001"/>
        </geometry>
        <material name="grey"/>
      </visual>

      <collision>
        <origin xyz="${0.0835-0.0860/2} 0.0 ${0.03525-0.04875/2}" rpy="0 0 0"/>
        <geometry>
          <box size="0.0860 0.0530 0.04875"/>
        </geometry>
      </collision>

      <inertial>
        <origin xyz="${0.0835-0.0860/2} 0.0 ${0.03525-0.04875/2}" rpy="0 0 0"/>
        <mass value="0.157" />
        <inertia  ixx="${1/12*0.157*(0.0860**2+0.04875**2)}" ixy="0.0" ixz="0.0"
                  iyy="${1/12*0.157*(0.0530**2+0.04875**2)}" iyz="0.0"
                  izz="${1/12*0.157*(0.0860**2+0.0530**2)}" />
      </inertial>
    </link>

    <!--  Joint 5: Forearm Upper -->
    <joint name="${prefix}_4_joint" type="revolute">
      <parent link="${prefix}_3_link"/>
      <child link="${prefix}_4_link"/>
      <origin xyz="0.0835 0.0 0.0" rpy="0 0 0"/>
      <axis xyz="1 0 0"/>
      <limit velocity="4.8" effort="1" lower="${-M_PI}" upper="${M_PI}" />
    </joint>

    <!--  Link 5: Forearm Upper -->
    <link name="${prefix}_4_link">
      <visual>
        <origin xyz="0 0 0" rpy="0 0 ${M_PI/2}"/>
        <geometry>
          <mesh filename="file://$(find sobit_light_description)/meshes/arm/omx1_link5.stl" scale="0.001 0.001 0.001"/>
        </geometry>
        <material name="grey"/>
      </visual>

      <collision>
        <origin xyz="${0.05175/2} 0.0 0.0" rpy="0 0 0"/>
        <geometry>
          <box size="0.05175 0.03700 0.0285"/>
        </geometry>
      </collision>

      <inertial>
        <origin xyz="${0.05175/2} 0.0 0.0" rpy="0 0 0"/>
        <mass value="0.093" />
        <inertia  ixx="${1/12*0.093*(0.05175**2+0.0285**2)}" ixy="0.0" ixz="0.0"
                  iyy="${1/12*0.093*(0.03700**2+0.0285**2)}" iyz="0.0"
                  izz="${1/12*0.093*(0.05175**2+0.0370**2)}" />
      </inertial>
    </link>

    <!--  Joint 6: Forearm Lower -->
    <joint name="${prefix}_5_joint" type="revolute">
      <parent link="${prefix}_4_link"/>
      <child link="${prefix}_5_link"/>
      <origin xyz="0.0405 0.0 0.0" rpy="0 0 0"/>
      <axis xyz="0 1 0"/>
      <limit velocity="4.8" effort="1" lower="${-M_PI/2}" upper="${M_PI/2}" />
    </joint>

    <!--  Link 6: Forearm Lower -->
    <link name="${prefix}_5_link">
      <visual>
        <origin xyz="0 0 0" rpy="0 0 ${M_PI/2}"/>
        <geometry>
          <mesh filename="file://$(find sobit_light_description)/meshes/arm/omx1_link6.stl" scale="0.001 0.001 0.001"/>
        </geometry>
        <material name="grey"/>
      </visual>

      <collision>
        <origin xyz="${0.064-0.0665/2} 0.0 ${0.03525-0.0465/2}" rpy="0 0 0"/>
        <geometry>
          <box size="0.0665 0.0410 0.0465"/>
        </geometry>
      </collision>

      <inertial>
        <origin xyz="${0.064-0.0665/2} 0.0 ${0.03525-0.0465/2}" rpy="0 0 0"/>
        <mass value="0.106" />
        <inertia  ixx="${1/12*0.106*(0.0665**2+0.0465**2)}" ixy="0.0" ixz="0.0"
                  iyy="${1/12*0.106*(0.0410**2+0.0465**2)}" iyz="0.0"
                  izz="${1/12*0.106*(0.0665**2+0.0410**2)}" />
      </inertial>
    </link>

    <!--  Joint 7: Wrist (Hand Base) -->
    <joint name="${prefix}_6_joint" type="revolute">
      <parent link="${prefix}_5_link"/>
      <child link="${prefix}_6_link"/>
      <origin xyz="0.064 0 0.0" rpy="0 0 0"/>
      <axis xyz="1 0 0"/>
      <limit velocity="4.8" effort="1" lower="${-M_PI}" upper="${M_PI}" />
    </joint>

    <!--  Link 7: Wrist (Hand Base) -->
    <link name="${prefix}_6_link">
      <visual>
        <origin xyz="0 0 0" rpy="0 0 ${M_PI/2}"/>
        <geometry>
          <mesh filename="file://$(find sobit_light_description)/meshes/arm/omx1_link7_hand_base.stl" scale="0.001 0.001 0.001"/>
        </geometry>
        <material name="grey"/>
      </visual>

      <collision>
        <origin xyz="${0.0505/2} 0.0 ${0.03775-0.0495/2}" rpy="0 0 0"/>
        <geometry>
          <box size="0.0505 0.0335 0.0495"/>
        </geometry>
      </collision>

      <inertial>
        <origin xyz="${0.0505/2} 0.0 ${0.03775-0.0495/2}" rpy="0 0 0"/>
        <mass value="0.134" />
        <inertia  ixx="${1/12*0.134*(0.0505**2+0.0495**2)}" ixy="0.0" ixz="0.0"
                  iyy="${1/12*0.134*(0.0335**2+0.0495**2)}" iyz="0.0"
                  izz="${1/12*0.134*(0.0505**2+0.0335**2)}" />
      </inertial>
    </link>

    <!--  Joint 8: Hand -->
    <joint name="${prefix}_hand_joint" type="fixed">
      <parent link="${prefix}_6_link"/>
      <child link="${prefix}_hand_link"/>
      <origin xyz="0.05 0.0 0.0" rpy="0 0 0"/>
    </joint>

    <!--  Link 8: Hand -->
    <link name="${prefix}_hand_link">
      <visual>
        <origin xyz="0 0 0" rpy="0 0 ${M_PI/2}"/>
        <geometry>
          <mesh filename="file://$(find sobit_light_description)/meshes/arm/omx1_link8_hand.stl" scale="0.001 0.001 0.001"/>
        </geometry>
        <material name="grey"/>
      </visual>

      <collision>
        <origin xyz="${0.008/2} 0.0 0.0" rpy="0 ${M_PI/2} 0"/>
        <geometry>
          <cylinder radius="0.011" length="0.008"/>
        </geometry>
      </collision>

      <inertial>
        <origin xyz="${0.008/2} 0.0 0.0" rpy="0 ${M_PI/2} 0"/>
        <mass value="0.003" />
        <inertia  ixx="${1/12*0.003*(3*0.011**2+0.008**2)}" ixy="0.0" ixz="0.0"
                  iyy="${1/12*0.003*(3*0.011**2+0.008**2)}" iyz="0.0"
                  izz="${1/12*0.003*(3*0.011**2+0.008**2)}" />
      </inertial>
    </link>


    <xacro:arm_transmission prefix="${prefix}" />

  </xacro:macro>
</robot>
