<?xml version="1.0" ?>
<!-- =================================================================================== -->
<!-- |    This document was autogenerated by xacro from sobit_light_robot.urdf.xacro   | -->
<!-- |    EDITING THIS FILE BY HAND IS NOT RECOMMENDED                                 | -->
<!-- =================================================================================== -->
<robot name="sobit_light">
  <material name="black">
    <color rgba="0.0 0.0 0.0 1.0"/>
  </material>
  <material name="white">
    <color rgba="1.0 1.0 1.0 1.0"/>
  </material>
  <material name="red">
    <color rgba="0.8 0.0 0.0 1.0"/>
  </material>
  <material name="blue">
    <color rgba="0.0 0.0 0.8 1.0"/>
  </material>
  <material name="green">
    <color rgba="0.0 0.8 0.0 1.0"/>
  </material>
  <material name="grey">
    <color rgba="0.5 0.5 0.5 1.0"/>
  </material>
  <material name="body">
    <color rgba="0.2175 0.2355 0.246 1.0"/>
  </material>
  <material name="tire">
    <color rgba="0.3 0.3 0.3 1.0"/>
  </material>
  <material name="aluminum">
    <color rgba="0.5 0.5 0.5 1"/>
  </material>
  <material name="plastic">
    <color rgba="0.1 0.1 0.1 1"/>
  </material>
  <!-- <link name="base_footprint"/> -->
  <!-- Base -->
  <!-- <joint name="${parent}_joint"
          type="fixed">
      <parent link="${parent}" />
      <child link="${prefix}_link" />
    </joint> -->
  <link name="base_link">
    <visual>
      <origin rpy="0 0 0" xyz="0.0435 0.0 0.0475"/>
      <geometry>
        <box size="0.387 0.240 0.095"/>
      </geometry>
      <material name="body"/>
    </visual>
    <collision>
      <origin rpy="0 0 0" xyz="0.0435 0.0 0.0475"/>
      <geometry>
        <box size="0.387 0.240 0.095"/>
      </geometry>
      <material name="body"/>
    </collision>
    <inertial>
      <mass value="6.4"/>
      <origin rpy="0 0 0" xyz="0 0 0"/>
      <inertia ixx="2.1342e-02" ixy="0" ixz="0" iyy="2.1342e-02" iyz="0" izz="4.2667e-02"/>
    </inertial>
  </link>
  <!-- Docking -->
  <joint name="docking_joint" type="prismatic">
    <parent link="base_link"/>
    <child link="docking_link"/>
    <axis xyz="0 0 1.0"/>
    <origin rpy="0 0 0" xyz="0 0 0"/>
    <limit effort="1.0" lower="0.0" upper="0.012" velocity="1.0"/>
  </joint>
  <link name="docking_link">
    <visual>
      <origin rpy="0 0 0" xyz="0 0 0.1075"/>
      <geometry>
        <cylinder length="0.015" radius="0.025"/>
      </geometry>
      <material name="body"/>
    </visual>
    <collision>
      <origin rpy="0 0 0" xyz="0 0 0.1075"/>
      <geometry>
        <cylinder length="0.015" radius="0.025"/>
      </geometry>
      <material name="body"/>
    </collision>
    <inertial>
      <mass value="0.2"/>
      <origin rpy="0 0 0" xyz="0 0 0"/>
      <inertia ixx="0.001" ixy="0" ixz="0" iyy="0.001" iyz="0" izz="0.001"/>
    </inertial>
  </link>
  <joint name="plate_bottom_joint" type="fixed">
    <origin rpy="0.0 0.0 0.0" xyz="0.0 0.0 0.1408"/>
    <parent link="base_link"/>
    <child link="plate_bottom_link"/>
  </joint>
  <link name="plate_bottom_link">
    <visual>
      <origin rpy="0.0 0.0 1.570796326795" xyz="0.0 0.0 0.0"/>
      <geometry>
        <mesh filename="file:///home/sobits/colcon_ws/install/sobit_light_description/share/sobit_light_description/meshes/body/plate_bottom.stl" scale="0.001 0.001 0.001"/>
      </geometry>
      <material name="black"/>
    </visual>
    <collision>
      <origin rpy="0.0 0.0 1.570796326795" xyz="0.0 0.0 -0.0045"/>
      <!-- <origin xyz="0.0 0.0 0.0" rpy="0.0 0.0 0.0" /> -->
      <geometry>
        <box size="0.3 0.3 0.009"/>
        <!-- <mesh filename="file://$(find sobit_light_description)/meshes/body/plate_bottom.stl" scale="0.001 0.001 0.001" /> -->
      </geometry>
    </collision>
    <inertial>
      <origin rpy="0.0 0.0 1.570796326795" xyz="0.0 0.0 -0.0045"/>
      <mass value="0.08"/>
      <inertia ixx="0.0006005399999999999" ixy="0.0" ixz="0.0" iyy="0.0006005399999999999" iyz="0.0" izz="0.0012"/>
      <!-- <inertia ixx="1.0" ixy="0.0" ixz="0.0"
                 iyy="1.0" iyz="0.0"
                 izz="1.0" /> -->
    </inertial>
  </link>
  <joint name="plate_middle_joint" type="fixed">
    <origin rpy="0.0 0.0 0.0" xyz="0.038000000000000006 0.0 0.11875"/>
    <parent link="plate_bottom_link"/>
    <child link="plate_middle_link"/>
  </joint>
  <link name="plate_middle_link">
    <visual>
      <origin rpy="0.0 0.0 1.570796326795" xyz="0.0 0.0 0.0"/>
      <geometry>
        <mesh filename="file:///home/sobits/colcon_ws/install/sobit_light_description/share/sobit_light_description/meshes/body/plate_middle.stl" scale="0.001 0.001 0.001"/>
      </geometry>
      <material name="black"/>
    </visual>
    <collision>
      <origin rpy="0.0 0.0 1.570796326795" xyz="0.0 0.0 -0.0045"/>
      <!-- <origin xyz="0.0 0.0 0.0" rpy="0.0 0.0 0.0" /> -->
      <geometry>
        <box size="0.3 0.3 0.009"/>
        <!-- <mesh filename="file://$(find sobit_light_description)/meshes/body/plate_middle.stl" scale="0.001 0.001 0.001" /> -->
      </geometry>
    </collision>
    <inertial>
      <origin rpy="0.0 0.0 1.570796326795" xyz="0.0 0.0 -0.0045"/>
      <mass value="0.08"/>
      <inertia ixx="0.0006005399999999999" ixy="0.0" ixz="0.0" iyy="0.0006005399999999999" iyz="0.0" izz="0.0012"/>
      <!-- <inertia ixx="1.0" ixy="0.0" ixz="0.0"
                 iyy="1.0" iyz="0.0"
                 izz="1.0" /> -->
    </inertial>
  </link>
  <joint name="back_base_joint" type="fixed">
    <parent link="plate_bottom_link"/>
    <child link="back_base_link"/>
    <origin rpy="0.0 0.0 0.0" xyz="-0.037000000000000005 0.0 0.0"/>
  </joint>
  <link name="back_base_link">
    <visual>
      <origin rpy="0.0 0.0 1.570796326795" xyz="0.0 0.0 0.0"/>
      <geometry>
        <mesh filename="file:///home/sobits/colcon_ws/install/sobit_light_description/share/sobit_light_description/meshes/back/back_base.stl" scale="0.001 0.001 0.001"/>
      </geometry>
      <material name="grey"/>
    </visual>
    <collision>
      <origin rpy="0.0 0.0 0.0" xyz="0.0 0.0 0.2585"/>
      <!-- <origin xyz="0.0 0.0 0.0" rpy="0.0 0.0 ${M_PI}" /> -->
      <geometry>
        <box size="0.02 0.02 0.517"/>
        <!-- <mesh filename="file://$(find sobit_light_description)/meshes/back/back_base.stl" scale="0.001 0.001 0.001" /> -->
      </geometry>
    </collision>
    <inertial>
      <origin rpy="0.0 0.0 0.0" xyz="0.0 0.0 0.2585"/>
      <mass value="0.5"/>
      <inertia ixx="0.011153708333333333" ixy="0.0" ixz="0.0" iyy="0.011153708333333333" iyz="0.0" izz="3.3333333333333335e-05"/>
      <!-- <inertia ixx="1.0" ixy="0.0" ixz="0.0"
                 iyy="1.0" iyz="0.0"
                 izz="1.0" /> -->
    </inertial>
  </link>
  <joint name="head_base_joint" type="fixed">
    <!-- <joint name="${prefix}_camera_base_joint" type="fixed"> -->
    <parent link="back_base_link"/>
    <!-- <child link="${prefix}_camera_base_link" /> -->
    <child link="head_base_link"/>
    <origin rpy="0.0 0.0 0.0" xyz="0.0 0.0 0.605"/>
  </joint>
  <link name="head_base_link">
    <!-- <link name="${prefix}_camera_base_link"> -->
    <visual>
      <origin rpy="0.0 0.0 1.570796326795" xyz="0.0 0.0 0.0"/>
      <geometry>
        <mesh filename="file:///home/sobits/colcon_ws/install/sobit_light_description/share/sobit_light_description/meshes/head/head_base.stl" scale="0.001 0.001 0.001"/>
      </geometry>
      <material name="black"/>
    </visual>
    <collision>
      <origin rpy="0.0 0.0 0.0" xyz="-0.024375 0.0 0.0"/>
      <!-- <origin xyz="0.0 0.0 0.0" rpy="${M_PI/2.0} 0.0 ${M_PI/2.0}" /> -->
      <geometry>
        <box size="0.15125 0.0285 0.044"/>
        <!-- <mesh filename="file://$(find sobit_light_description)/meshes/head/head_camera_base.stl" scale="0.001 0.001 0.001" /> -->
      </geometry>
    </collision>
    <inertial>
      <origin rpy="0.0 0.0 0.0" xyz="-0.024375 0.0 0.0"/>
      <mass value="0.08"/>
      <inertia ixx="0.00016541708333333332" ixy="0.0" ixz="0.0" iyy="1.8321666666666664e-05" iyz="0.0" izz="0.00015792541666666667"/>
      <!-- <inertia ixx="1.0" ixy="0.0" ixz="0.0"
                 iyy="1.0" iyz="0.0"
                 izz="1.0" /> -->
    </inertial>
  </link>
  <!-- <joint name="${prefix}_camera_pan_joint" type="revolute"> -->
  <joint name="head_pan_joint" type="revolute">
    <parent link="head_base_link"/>
    <!-- <parent link="${prefix}_camera_base_link" /> -->
    <child link="head_pan_link"/>
    <!-- <child link="${prefix}_camera_pan_link" /> -->
    <origin rpy="0.0 0.0 0.0" xyz="0.012 0.0 0.041"/>
    <axis xyz="0 0 1"/>
    <limit effort="30" lower="-3.14159265359" upper="3.14159265359" velocity="1.570796326795"/>
  </joint>
  <link name="head_pan_link">
    <!-- <link name="${prefix}_camera_pan_link"> -->
    <visual>
      <origin rpy="0.0 0.0 1.570796326795" xyz="0.0 0.0 0.0"/>
      <geometry>
        <mesh filename="file:///home/sobits/colcon_ws/install/sobit_light_description/share/sobit_light_description/meshes/head/head_pan.stl" scale="0.001 0.001 0.001"/>
      </geometry>
      <material name="black"/>
    </visual>
    <collision>
      <origin rpy="0.0 0.0 0.0" xyz="0.0 0.0 0.022875"/>
      <!-- <origin xyz="0.0 0.0 0.0" rpy="0.0 0.0 ${M_PI/2.0}" /> -->
      <geometry>
        <box size="0.0285 0.037 0.03525"/>
        <!-- <mesh filename="file://$(find sobit_light_description)/meshes/head/head_camera_pan.stl" scale="0.001 0.001 0.001" /> -->
      </geometry>
    </collision>
    <inertial>
      <origin rpy="0.0 0.0 1.570796326795" xyz="0.0 0.0 0.022875"/>
      <mass value="0.08"/>
      <inertia ixx="1.3698749999999998e-05" ixy="0.0" ixz="0.0" iyy="1.7410416666666662e-05" iyz="0.0" izz="1.4541666666666667e-05"/>
      <!-- <inertia ixx="1.0" ixy="0.0" ixz="0.0"
                 iyy="1.0" iyz="0.0"
                 izz="1.0" /> -->
    </inertial>
  </link>
  <joint name="head_tilt_joint" type="revolute">
    <!-- <joint name="${prefix}_camera_tilt_joint" type="revolute"> -->
    <parent link="head_pan_link"/>
    <!-- <parent link="${prefix}_camera_pan_link" /> -->
    <child link="head_tilt_link"/>
    <!-- <child link="${prefix}_camera_tilt_link" /> -->
    <origin rpy="0.0 0.0 0.0" xyz="0.0 0.0 0.0405"/>
    <axis xyz="0 -1 0"/>
    <limit effort="30" lower="-1.570796326795" upper="1.570796326795" velocity="1.570796326795"/>
  </joint>
  <link name="head_tilt_link">
    <!-- <link name="${prefix}_camera_tilt_link"> -->
    <visual>
      <origin rpy="0.0 0.0 1.570796326795" xyz="0.0 0.0 0.0"/>
      <geometry>
        <mesh filename="file:///home/sobits/colcon_ws/install/sobit_light_description/share/sobit_light_description/meshes/head/head_tilt.stl" scale="0.001 0.001 0.001"/>
      </geometry>
      <material name="black"/>
    </visual>
    <collision>
      <origin rpy="0.0 0.0 0.0" xyz="0.0 0.0 0.03375"/>
      <!-- <origin xyz="0.0 0.0 0.0" rpy="0.0 0.0 ${M_PI/2.0}" /> -->
      <geometry>
        <box size="0.046 0.0466 0.0115"/>
        <!-- <mesh filename="file://$(find sobit_light_description)/meshes/head/head_camera_tilt.stl" scale="0.001 0.001 0.001" /> -->
      </geometry>
    </collision>
    <inertial>
      <origin rpy="0.0 0.0 0.0" xyz="0.0 0.0 0.03375"/>
      <mass value="0.08"/>
      <inertia ixx="1.4988333333333332e-05" ixy="0.0" ixz="0.0" iyy="1.5358733333333336e-05" iyz="0.0" izz="2.8583733333333332e-05"/>
      <!-- <inertia ixx="1.0" ixy="0.0" ixz="0.0"
                 iyy="1.0" iyz="0.0"
                 izz="1.0" /> -->
    </inertial>
  </link>
  <position_joint_transmission joint="head_pan_joint" reduction="1"/>
  <position_joint_transmission joint="head_tilt_joint" reduction="1"/>
  <!-- Left wheel -->
  <joint name="base_l_drive_wheel_joint" type="continuous">
    <parent link="base_link"/>
    <child link="base_l_drive_wheel_link"/>
    <origin rpy="0 0 0" xyz="0.0 0.100 0.045"/>
    <axis xyz="0 1 0"/>
    <limit effort="100" velocity="10"/>
  </joint>
  <link name="base_l_drive_wheel_link">
    <visual>
      <origin rpy="1.570796326795 0 0" xyz="0 0 0"/>
      <geometry>
        <cylinder length="0.025" radius="0.045"/>
      </geometry>
      <material name="tire"/>
    </visual>
    <collision>
      <origin rpy="1.570796326795 0 0" xyz="0 0 0"/>
      <geometry>
        <cylinder length="0.025" radius="0.045"/>
      </geometry>
      <material name="tire"/>
    </collision>
    <inertial>
      <origin rpy="0 0 0" xyz="0 0 0"/>
      <mass value="0.2"/>
      <inertia ixx="0.001" ixy="0" ixz="0" iyy="0.001" iyz="0" izz="0.001"/>
    </inertial>
  </link>
  <!-- Right wheel -->
  <joint name="base_r_drive_wheel_joint" type="continuous">
    <parent link="base_link"/>
    <child link="base_r_drive_wheel_link"/>
    <origin rpy="0 0 0" xyz="0.0 -0.100 0.045"/>
    <axis xyz="0 1 0"/>
    <limit effort="100" velocity="10"/>
  </joint>
  <link name="base_r_drive_wheel_link">
    <visual>
      <origin rpy="1.570796326795 0 0" xyz="0 0 0"/>
      <geometry>
        <cylinder length="0.025" radius="0.045"/>
      </geometry>
      <material name="tire"/>
    </visual>
    <collision>
      <origin rpy="1.570796326795 0 0" xyz="0 0 0"/>
      <geometry>
        <cylinder length="0.025" radius="0.045"/>
      </geometry>
      <material name="tire"/>
    </collision>
    <inertial>
      <origin rpy="0 0 0" xyz="0 0 0"/>
      <mass value="0.2"/>
      <inertia ixx="0.001" ixy="0" ixz="0" iyy="0.001" iyz="0" izz="0.001"/>
    </inertial>
  </link>
  <joint name="lidar_joint" type="fixed">
    <parent link="base_link"/>
    <child link="laser_frame"/>
    <origin rpy="0 0 1.570796326795" xyz="0.156 0 0.1049"/>
  </joint>
  <link name="laser_frame">
    <inertial>
      <origin rpy="0 0 0" xyz="0 0 0"/>
      <mass value="0.2"/>
      <inertia ixx="0.001" ixy="0" ixz="0" iyy="0.001" iyz="0" izz="0.001"/>
    </inertial>
  </link>
  <joint name="tof_joint" type="fixed">
    <parent link="base_link"/>
    <child link="tof_link"/>
    <origin rpy="-0.7853981633975 0 -1.570796326795" xyz="0.221 0.0 0.0418"/>
  </joint>
  <link name="tof_link">
    <inertial>
      <origin rpy="0 0 0" xyz="0 0 0"/>
      <mass value="0.2"/>
      <inertia ixx="0.001" ixy="0" ixz="0" iyy="0.001" iyz="0" izz="0.001"/>
    </inertial>
  </link>
  <joint name="imu_joint" type="fixed">
    <parent link="base_link"/>
    <child link="imu_link"/>
    <origin rpy="0 0 0" xyz="0.0756 -0.0655 0.05146"/>
  </joint>
  <link name="imu_link"/>
  <joint name="speaker_base_joint" type="fixed">
    <parent link="back_base_link"/>
    <child link="speaker_base_link"/>
    <origin rpy="0.0 0.0 0.0" xyz="0.050 0.0 0.510"/>
  </joint>
  <link name="speaker_base_link">
    <visual>
      <origin rpy="-0.3490658503988889 0.0 1.570796326795" xyz="0.0 0.0 0.0"/>
      <geometry>
        <mesh filename="file:///home/sobits/colcon_ws/install/sobit_light_description/share/sobit_light_description/meshes/sensor/speaker.stl" scale="0.001 0.001 0.001"/>
      </geometry>
      <material name="black"/>
    </visual>
    <collision>
      <origin rpy="0.0 0.0 1.570796326795" xyz="0.0 0.0 0.0"/>
      <geometry>
        <mesh filename="file:///home/sobits/colcon_ws/install/sobit_light_description/share/sobit_light_description/meshes/sensor/speaker.stl" scale="0.001 0.001 0.001"/>
      </geometry>
      <material name="black"/>
    </collision>
    <inertial>
      <origin rpy="0.0 0.0 1.570796326795" xyz="0.0 0.0 0.0"/>
      <mass value="0.09507172"/>
      <inertia ixx="0.00024348659756333332" ixy="0.0" ixz="0.0" iyy="5.3557068933333334e-05" iyz="0.0" izz="0.00020064094241666665"/>
    </inertial>
  </link>
  <!-- <gazebo reference="${prefix}_base_link">
      <material>Gazebo/Black</material>
    </gazebo> -->
  <joint name="head_camera_base_joint" type="fixed">
    <origin rpy="0.0 0.0 0.0" xyz="0.05815 0.0 0.12050335"/>
    <parent link="head_tilt_link"/>
    <child link="head_camera_base_link"/>
  </joint>
  <link name="head_camera_base_link"/>
  <!-- camera body, with origin at bottom screw mount -->
  <joint name="head_camera_joint" type="fixed">
    <origin rpy="0.0 0.0 0.0" xyz="0.0 0.0 0.0"/>
    <parent link="head_camera_base_link"/>
    <child link="head_camera_bottom_screw_frame"/>
  </joint>
  <link name="head_camera_bottom_screw_frame"/>
  <joint name="head_camera_link_joint" type="fixed">
    <origin rpy="0 0 0" xyz="0.010600000000000002 0.0175 0.0125"/>
    <parent link="head_camera_bottom_screw_frame"/>
    <child link="head_camera_link"/>
  </joint>
  <link name="head_camera_link">
    <visual>
      <!-- the mesh origin is at front plate in between the two infrared camera axes -->
      <origin rpy="1.5707963267948966 0 1.5707963267948966" xyz="0.0043 -0.0175 0"/>
      <geometry>
        <mesh filename="file:///home/sobits/colcon_ws/install/realsense2_description/share/realsense2_description/meshes/d435.dae"/>
      </geometry>
    </visual>
    <collision>
      <origin rpy="0 0 0" xyz="0 -0.0175 0"/>
      <geometry>
        <box size="0.02505 0.09 0.025"/>
      </geometry>
    </collision>
    <inertial>
      <!-- The following are not reliable values, and should not be used for modeling -->
      <mass value="0.072"/>
      <origin xyz="0 0 0"/>
      <inertia ixx="0.003881243" ixy="0.0" ixz="0.0" iyy="0.000498940" iyz="0.0" izz="0.003879257"/>
    </inertial>
  </link>
  <joint name="camera_front_joint" type="fixed">
    <parent link="base_link"/>
    <child link="camera_front_link"/>
    <origin rpy="-1.570796326795 0 -1.570796326795" xyz="0.20959999999999998 0 0.070"/>
  </joint>
  <link name="camera_front_link">
    <inertial>
      <origin rpy="0 0 0" xyz="0 0 0"/>
      <mass value="0.2"/>
      <inertia ixx="0.001" ixy="0" ixz="0" iyy="0.001" iyz="0" izz="0.001"/>
    </inertial>
  </link>
  <joint name="camera_back_joint" type="fixed">
    <parent link="base_link"/>
    <child link="camera_back_link"/>
    <origin rpy="-1.570796326795 0 1.570796326795" xyz="-0.13999999999999999 0 0.070"/>
  </joint>
  <link name="camera_back_link">
    <inertial>
      <origin rpy="0 0 0" xyz="0 0 0"/>
      <mass value="0.2"/>
      <inertia ixx="0.001" ixy="0" ixz="0" iyy="0.001" iyz="0" izz="0.001"/>
    </inertial>
  </link>
  <ros2_control name="IgnitionSystem" type="system">
    <hardware>
      <plugin>ign_ros2_control/IgnitionSystem</plugin>
      <!-- <plugin>gz_ros2_control/GazeboSimSystem</plugin> -->
    </hardware>
    <joint name="base_l_drive_wheel_joint">
      <command_interface name="velocity">
        <param name="min">-1</param>
        <param name="max">1</param>
      </command_interface>
      <state_interface name="position"/>
      <state_interface name="velocity"/>
    </joint>
    <joint name="base_r_drive_wheel_joint">
      <command_interface name="velocity">
        <param name="min">-10</param>
        <param name="max">10</param>
      </command_interface>
      <state_interface name="position"/>
      <state_interface name="velocity"/>
    </joint>
  </ros2_control>
  <!-- <gazebo reference="${prefix}_base_link">
      <material>Gazebo/Black</material>
    </gazebo> -->
  <gazebo reference="laser_frame">
    <!-- <material>Gazebo/Black</material> -->
    <sensor name="laser" type="ray">
      <pose> 0 0 0 0 0 0 </pose>
      <visualize>true</visualize>
      <update_rate>10</update_rate>
      <ray>
        <scan>
          <horizontal>
            <samples>360</samples>
            <min_angle>-3.14</min_angle>
            <max_angle>3.14</max_angle>
          </horizontal>
        </scan>
        <range>
          <min>0.3</min>
          <max>12</max>
        </range>
      </ray>
      <plugin filename="libgazebo_ros_ray_sensor.so" name="laser_controller">
        <ros>
          <argument>~/out:=scan</argument>
        </ros>
        <output_type>sensor_msgs/LaserScan</output_type>
        <frame_name>laser_frame</frame_name>
      </plugin>
    </sensor>
  </gazebo>
  <!-- Add Gazebo: plugins, sensors -->
  <gazebo>
    <!-- <plugin filename="libign_ros2_control-system.so" name="ign_ros2_control::IgnitionROS2ControlPlugin"> -->
    <plugin filename="ign_ros2_control-system" name="ign_ros2_control::IgnitionROS2ControlPlugin">
      <!-- <plugin filename="gz_ros2_control-system" name="gz_ros2_control::GazeboSimROS2ControlPlugin"> -->
      <parameters>/home/sobits/colcon_ws/install/sobit_light_control/share/sobit_light_control/config/ros_controllers.yaml</parameters>
      <!-- <parameters>$(find sobit_light_control)/config/gaz_ros2_ctl_use_sim.yaml</parameters> -->
    </plugin>
  </gazebo>
</robot>
