<?xml version="1.0" encoding="UTF-8" ?>
<robot name="head" xmlns:xacro="http://ros.org/wiki/xacro">
  <xacro:include filename="$(find sobit_light_description)/urdf/head/head.transmission.xacro" />
  
  <xacro:macro name="head" params="prefix parent">
    <joint name="${prefix}_base_joint" type="fixed">
    <!-- <joint name="${prefix}_camera_base_joint" type="fixed"> -->
      <parent link="${parent}" />
      <!-- <child link="${prefix}_camera_base_link" /> -->
      <child link="${prefix}_base_link" />
      <origin xyz="0.0 0.0 0.605" rpy="0.0 0.0 0.0" />
    </joint>

    <link name="${prefix}_base_link">
    <!-- <link name="${prefix}_camera_base_link"> -->
      <visual>
        <origin xyz="0.0 0.0 0.0" rpy="0.0 0.0 ${M_PI/2.0}" />
        <geometry>
          <mesh filename="file://$(find sobit_light_description)/meshes/head/head_base.stl" scale="0.001 0.001 0.001" />
        </geometry>
        <material name="black" />
      </visual>

      <collision>
        <origin xyz="0.0 0.0 ${0.039-0.069/2}" rpy="0 0 0"/>
        <geometry>
          <box size="0.0565 0.0385 0.0690"/>
        </geometry>
      </collision>

      <inertial>
        <origin xyz="0.0 0.0 ${0.039-0.069/2}" rpy="0 0 0"/>
        <mass value="0.145" />
        <inertia  ixx="${1/12*0.145*(0.0565**2+0.0690**2)}" ixy="0.0" ixz="0.0"
                  iyy="${1/12*0.145*(0.0385**2+0.0690**2)}" iyz="0.0"
                  izz="${1/12*0.145*(0.0565**2+0.0385**2)}" />
      </inertial>
    </link>


    <joint name="${prefix}_yaw_joint" type="revolute">
      <parent link="${prefix}_base_link" />
      <child link="${prefix}_yaw_link" />
      <origin xyz="0.012 0.0 0.041" rpy="0.0 0.0 0.0" />
      <axis xyz="0 0 1" />
      <limit effort="30" lower="${-M_PI}" upper="${M_PI}" velocity="${M_PI/2.0}" />
    </joint>

    <link name="${prefix}_yaw_link">
      <visual>
        <origin xyz="0.0 0.0 0.0" rpy="0.0 0.0 ${M_PI/2.0}" />
        <geometry>
          <mesh filename="file://$(find sobit_light_description)/meshes/head/head_pan.stl" scale="0.001 0.001 0.001" />
        </geometry>
        <material name="black" />
      </visual>

      <collision>
        <origin xyz="0.0 0.0 ${0.05175/2}" rpy="0 0 0"/>
        <geometry>
          <box size="0.0285 0.0370 0.05175"/>
        </geometry>
      </collision>

      <inertial>
        <origin xyz="0.0 0.0 ${0.05175/2}" rpy="0 0 0"/>
        <mass value="0.089" />
        <inertia  ixx="${1/12*0.089*(0.0285**2+0.05175**2)}" ixy="0.0" ixz="0.0"
                  iyy="${1/12*0.089*(0.0370**2+0.05175**2)}" iyz="0.0"
                  izz="${1/12*0.089*(0.0285**2+0.0370**2)}" />
      </inertial>
    </link>


    <joint name="${prefix}_pitch_joint" type="revolute">
      <parent link="${prefix}_yaw_link" />
      <child link="${prefix}_pitch_link" />
      <origin xyz="0.0 0.0 0.0405" rpy="0.0 0.0 0.0" />
      <axis xyz="0 -1 0" />
      <limit effort="30" lower="${-M_PI/2.0}" upper="${M_PI/2.0}" velocity="${M_PI/2.0}" />
    </joint>

    <link name="${prefix}_pitch_link">
      <visual>
        <origin xyz="0.0 0.0 0.0" rpy="0.0 0.0 ${M_PI/2.0}" />
        <geometry>
          <mesh filename="file://$(find sobit_light_description)/meshes/head/head_tilt.stl" scale="0.001 0.001 0.001" />
        </geometry>
        <material name="black" />
      </visual>

      <collision>
        <origin xyz="${0.0725-0.150/2} 0.0 ${0.028+0.1275/2}" rpy="0 0 0"/>
        <geometry>
          <box size="0.150 0.200 0.1275"/>
        </geometry>
      </collision>

      <inertial>
        <origin xyz="${0.0725-0.150/2} 0.0 ${0.028+0.1275/2}" rpy="0 0 0"/>
        <mass value="0.904" />
        <inertia  ixx="${1/12*0.904*(0.150**2+0.1275**2)}" ixy="0.0" ixz="0.0"
                  iyy="${1/12*0.904*(0.200**2+0.1275**2)}" iyz="0.0"
                  izz="${1/12*0.904*(0.150**2+0.200**2)}" />
      </inertial>
    </link>


    <xacro:head_transmission prefix="${prefix}" />

  </xacro:macro>
</robot>
